Workbook

Sheet Refurbishment
A1: Refurbishment Specification
A2: Property: | B2: Hillcroft | K2: Property Front View
A3: Address: | B3: Hillcroft, Lightshaw Lane, Golborne, WARRINGTON, Cheshire, WA3 3UH, United Kingdom | K3: #VALUE!
A4: Orbis/Keysafe: | B4: Keysafe / Orbis Alarm / Padlock : tenanted
D5: Specification Standard | G5: Notes Windows, doors and timber flagged on HHSRS report, as well as kitchen and utility units
A7: Item | B7: Type | D7: Bronze
A8: Internal Decoration | B8: Walls | D8: Dulux almond white | G8: Please Check Notes as colour might differ
B9: Tiles | D9: Metro Tiles | G9: 8
B10: Woodwork | D10: Dulux Satin or similar | G10: Not Required
A11: Flooring | B11: Linoleum | D11: Medium hard wearing vinyl, latex/plywood where required | G11: No carpets in bathrooms as standard
B12: Carpets | D12: =IF(D7="Gold","Heavy domestic type no less than 32oz per sq yard pile height no less than 7mm and no greater than 9mm colour to carry stain warrantee colour",IF(D7="Silver","Heavy domestic with minimum pile per m sq and as specified",IF(D7="Bronze","Mid domestic type pile height no less than 7mm"))) -> Mid domestic type pile height no less than 7mm | G12: Colour to be of a neutral tone eg straw, doe skin, fawn or beige. Doormat inset to any external accesses
B13: Underlay | D13: =IF(D7="Gold","Cloudnine",IF(D7="Silver","Cloudnine",IF(D7="Bronze","Cloudnine"))) -> Cloudnine
A14: External Decoration | B14: Walls | D14: Like for like unless specified
B15: Woodwork | D15: Like for like unless specified | G15: Strip, repair and 2 coats
A16: Replacement | B16: Kitchen | C16: Cooker to specify | D16: =IF(D7="Gold","16-18mm carcus",IF(D7="Silver","16-18mm carcus",IF(D7="Bronze","14mm carcus"))) -> 14mm carcus | G16: All soft close, colour/design to specify, Howdens
B17: Bathroom | D17: To Specify on inspection
A22: Room | B22: Type | C22: Required Yes or No | D22: Further Information | H22: Cost | I22: Capital/Revenue
A23: Ground Floor | H23: Cost per item | I23: Please Select | K23: Photographs
A24: Kitchen/Diner | B24: Ceiling | C24: No | I24: Revenue
B25: Walls | C25: No | I25: Revenue
B26: Woodwork | C26: No | I26: Revenue
B27: Floors | C27: No | I27: Revenue
B28: Windows | C28: No | I28: Revenue
B29: Curtains/Rails | C29: No | I29: Revenue
B30: Skirting | C30: No | I30: Revenue
B31: Door | C31: No | I31: Revenue
B32: Fridge | C32: No
B33: Units & Appliances | C33: Yes | D33: HHSRS - Allow for replacement kitchen appliances to bring the kitchen to a modern standard like-for-like, cooker and dish washer currently faulty. Allow for modernised oven, cooker and dishwasher. Fridge is consistently getting condensated and mouldy. Allow for replacement refridgerator. | H33: 3000 | I33: Revenue | J33: Total
B34: Additional | C34: No | I34: Revenue | J34: =SUM(H24:H34) -> 3000
A35: Sitting Room | B35: Ceiling | C35: Yes | D35: Where damp remedials have been replastered, allow to prepare and redecorate like-for-like including upper skirting | H35: 500 | I35: Revenue
B36: Walls | C36: No | I36: Revenue
B37: Woodwork | C37: No | I37: Revenue
B38: Floors | C38: No | I38: Revenue
B39: Windows | C39: No | I39: Revenue
B40: Curtains/Rails | C40: Yes | D40: Allow for replacement blinds to french door, ensuring opening mechanisms are functioning | H40: 465 | I40: Revenue
B41: Skirting | C41: No | I41: Revenue
B42: Additional | C42: No | I42: Revenue
B43: Additional | C43: No | I43: Revenue
B44: Additional | C44: No | I44: Revenue
B45: Additional | C45: No | I45: Revenue
...

Sheet List Look up
A3: Additional
A4: Annex Bathroom
A5: Annex Bedroom 1
A6: Annex Kitchen
A7: Annex Living
A8: Bathroom 1
A9: Bathroom 2
A10: Bathroom 3
A11: Bedroom 1
A12: Bedroom 2
A13: Bedroom 3
A14: Bedroom 4
... A42: Utility 2

Sheet General Specification
A1: General Specification
A2: Materials (External Works)
A3: All materials shall be of approved manufacture and are to be delivered to the site in sealed containers with the makers name and description of the contents clearly marked thereon. If the contractor proposes to use a brand other than one of those listed he is to state the brands he wishes to use when submitting his estimates.
A4: Paint for external use and domestic properties shall be an approved oil based paint. Undercoat and gloss with appropriate primer for wood iron as the case may be. In all other instances paint shall be ICI Dulux undercoat and gloss with pink primer. NOTE: NO Lead based paints to be used on Farm Buildings.
A5: All Primers, undercoats and gloss paints will be supplied by the same manufacturer for use together.
A6: Sadolin to external treated woodwork.
A7: Bitumastic shall be Wailes-Dove heavy duty Black Bitumastic solution.
A8: Putty for woodwork shall be best quality linseed oil putty to BS544:1069 type I
A9: Secomastic 'sealastic' shall be used for making good joints in iron gutters.
A10: PVC gutters to be checked, realigned if necessary
A11: Any asbestos guttering will be identified in a removal and demolition asbestos survey carried out in accordance to the specification provided to the contractor and maintenance of these gutters will be determined by the course of action highlighted in that report.
A12: General Workmanship (External Repairs)
A13: Painting | C13: All materials, particularly regarding thinning and drying between coats, are to be used strictly in accordance with the maker's instructions. No paint shall be applied to surfaces that are damp or wet, or in foggy, wet or frosty weather.
C14: All surfaces now painted or treated are to be included unless specifically stated otherwise
C15: The properties to be treated are set out in the schedule and include any outbuildings, gates and fences which comprise part of the holding unless specifically noted in the schedule as 'not to be painted'.
A16: Ease and Adjust | C16: The edges of doors and opening windows to be eased as necessary before painting so that after application of the paint they fit well and can be opened and shut without difficulty. Where practical and necessary, unpainted door furniture is to be removed prior to painting, re-fixing thereafter and left clean and free from paint
A17: Touch up and Make Good | C17: After any defects have been made good, all paintwork to be touched up to general specification
A18: Inspect Gutters and Downpipes | C18: The Contractor to ensure, before painting, that soil and vent pipes and rainwater goods are in sound condition and operating correctly. Adjust falls, rejoint and replace defective or missing sections as detailed in schedule or report to the Surveyors such defects not included.
A19: Cracked or Broken Glass Putty | C19: Any broken or cracked glass to be replaced. Any loose or cracked putties to be raked out and made good before painting Proceeds. Prime rebates prior to puttying.
A20: Painting and Preparation of Surfaces | C20: Woodwork - all cracked, flacking and blistered work to be burnt off, rubbed down, knotted, primed, stopped up and a coat of priming paint applied of the same brand as the subsequent coats. Where hardwood window sills have been burnt off, these are to be primed with aluminium paint.
C21: All other sound surfaces to be washed off, rubbed down with wet abrasive paper and prepared inluding the necessary stopping up.
C22: The paint to be applied to both woodwork and ironwork. Undercoats and gloss is to be of an approved manufacturer or as otherwise approved by the Surveyors. Knot, prime and stop new or bare woodwork and finish with one undercoat and two gloss coats. Existing paintwork that is sound shall be rubbed down and brought forward one undercoat and one gloss coat.
C23: Generally - the Contractor is to pay particular attention to the painting of the following items:- The tops, bottoms and side of windows and doors opening outward. The bargeboards, rafters and purlin ends. Outward opening doors to be treated both sides. Where rainwater downpipes are not accessible to effectively paint behind they shall be removed for painting and then refixed.
A24: Window and Door Openings | C24: All pointing around windows, sills and door frames to be checked, raked out where necessary and made good prior to redecorations.
A25: Roof Overhauls | C25: Replace or re-set and slippted or cracked tiles or slates, rebedding ridge and hip pieces and making good mortar bedding at verges and at the eaves. Clean valleys, taking care not to injure leadwork, and ensure that all leadwork flashings and soakers are properly positioned effectively. Inspect chimney stacks and secure loose pots, making good mortar flaunchings. Advise of any defective pointing to stacks that has not been specified for repair.
A26: Materials (Internal Works)
A27: All materials shall be of approved manufacture and are to be delivered to the site in sealed containers with the makers name and description of the contents clearly marked thereon. If the contractor proposes to use a brand other than one of those listed he is to state the brands he wishes to use when submitting his estimates.
A28: Paint for internal decoration is to be Dulux or of a similar quality. This applies to all internal masonary and woodwork paint.
A29: All Primers, undercoats and gloss paints will be supplied by the same manufacturer for use together. Woodwork should be Dulux Satin or similar.
A30: Floorcoverings - all carpets are to be replaced unless stated, these will be listed as either Gold/Silver which will be based on a twist or loop pile carpet not less than 28oz in weight and between 6mm and 12mm in terms of pile height with a hessian, jute or manmade fibre backing. Some areas of a property will require more durable carpets than others due to increased traffic. Underlay is to be of a good density on all specifications with Cloud 9 being the preferred brand although similar will be considered.
A31: Linoleum - all linoleum floors are to be of a durable hard wearing medium range value unless stated. Carpeted floors to bathrooms are to be replaced with linoleum unless otherwise stated.
A32: Tiles will be of white metro tile design unless specified
A33: All failed double glazing units are to be replaced with like for like units.
A34: Taps and other bathroom fittings found to be faulty are to be replaced like for like unless stated or unless advised otherwise.
A35: Door furniture found to be faulty should be replaced like for like unless the fault is with the style of furniture.
A36: All freestanding appliances are to be removed from the property and all faulty integrated appliances are to be replaced like for like unless stated or unless a repair can be done more economically
A37: Cookers found to be faulty are to be replaced like for like unless specified
... A39: General Workmanship (Internal Repairs)
A40: Painting | C40: All masonary surfaces should be stripped of paper unless otherwise specified. All surfaces now painted are to be included unless stated. Surfaces are to be painted with 2 coats unless further coats are required.
C41: The rooms that are to be decorated are set out in the schedule below.
...

Sheet Compliance
A1: =Refurbishment!B3 -> Hillcroft, Lightshaw Lane, Golborne, WARRINGTON, Cheshire, WA3 3UH, United Kingdom
A2: COMPLIANCE/SERVICE
A3: COMPLIANCE SERVICES | C3: CONTRACTOR | D3: COST (Excl VAT) | E3: Category
A4: EICR | C4: Revised compliance certificate required upon completion | D4: 600 | E4: Compliance
A5: PAT | C5: Revised compliance certificate required upon completion | D5: 360 | E5: Compliance
A6: Gas/Oil/Solid fuel servicing + Option 1 drain down | C6: Revised compliance certificate required upon completion | D6: 540 | E6: Compliance
A7: HHSRS Survey | C7: Revised compliance certificate required upon completion | D7: 360 | E7: Compliance
A8: Asbestos Survey incl. Management Plan | C8: Revised compliance certificate required upon completion (subject to R&D survey findings) | D8: 1440 | E8: Compliance
A9: Legionella Risk Assessment | C9: Revised compliance certificate required upon completion | D9: 300 | E9: Compliance
A10: Chimney Sweeping (IF APPLICABLE) | D10: 180 | E10: Compliance
A11: Radon Test (IF APPLICABLE) | D11: 360 | E11: Compliance
A12: Empty/service Septic Tank (IF APPLICABLE) | E12: Compliance
C13: Total Compliance Servicing | D13: =SUM(D4:D12) -> 4140
A15: Electrical Compliance Remedials (including Detectors)
A16: ITEM | D16: Cost | E16: Category
E17: Revenue
E18: Revenue
E19: Revenue
E20: Revenue
E21: Revenue
E22: Revenue
E23: Revenue
E24: Revenue
E25: Revenue
E26: Revenue
E27: Revenue
E32: Revenue
... E38: Revenue
A39: Allow for compliance retest upon completion of works | D39: 420 | E39: Revenue
A40: Add more rows as required
C41: TOTAL | D41: =SUM(D17:D40) -> 420
A44: Clean certificates to be provided (as well as the main electrical cert) : FHN6 (B-F) is a certificate of design, installation and commissioning of a fire detection alarm system grade B,C,D,E or F in a domestic property. This certificate should detail the number of smoke detector, heat detectors and CO detector in the “extent of the fire detection and alarm system covered by this certificate” section. The Minor Works of installation works certificate (IMN4) clarifies that the installation of the detectors have been designed, constructed, inspected, tested and verified in accordance with current electrical regulations.
A45: Gas/Oil/Solid Fuel Remedials* | D45: Cost | E45: Category
E46: Revenue
E47: Revenue
E48: Revenue
E49: Revenue
E50: Revenue
E51: Revenue
E52: Revenue
...

Sheet New Cost Breakdown 
A1: =Refurbishment!B3 -> Hillcroft, Lightshaw Lane, Golborne, WARRINGTON, Cheshire, WA3 3UH, United Kingdom
A2: Cost Break Down
A3: Category | B3: Cost
A4: Decoration | B4: =SUM(Refurbishment!H24:H26)+SUM(Refurbishment!H35:H37)+SUM(Refurbishment!H48:H50)+SUM(Refurbishment!H59:H61)+SUM(Refurbishment!H70:H72)+SUM(Refurbishment!H87:H89)+SUM(Refurbishment!H101:H103)+SUM(Refurbishment!H113:H115)+SUM(Refurbishment!H123:H125)+SUM(Refurbishment!H133:H135)+SUM(Refurbishment!H143:H145)+SUM(Refurbishment!H153:H155)+SUM(Refurbishment!H164:H166)+SUM(Refurbishment!H174:H176)+SUM(Refurbishment!H204:H206)+SUM(Refurbishment!H214:H216)+SUM(Refurbishment!H224:H226)+SUM(Refurbishment!H235:H237)+SUM(Refurbishment!H245:H247)+SUM(Refurbishment!H255:H257)+SUM(Refurbishment!H265:H267)+SUM(Refurbishment!H275:H277)+SUM(Refurbishment!H285:H287)+SUM(Refurbishment!H295:H297)+SUM(Refurbishment!H184:H186)+SUM(Refurbishment!H194:H196) -> 1600
A5: Floor coverings | B5: =Refurbishment!H27+Refurbishment!H38+Refurbishment!H51+Refurbishment!H62+Refurbishment!H73+Refurbishment!H90+Refurbishment!H104+Refurbishment!H116+Refurbishment!H126+Refurbishment!H136+Refurbishment!H146+Refurbishment!H156+Refurbishment!H167+Refurbishment!H177+Refurbishment!H207+Refurbishment!H217+Refurbishment!H227+Refurbishment!H238+Refurbishment!H248+Refurbishment!H258+Refurbishment!H268+Refurbishment!H278+Refurbishment!H288+Refurbishment!H298+Refurbishment!H187+Refurbishment!H197 -> 0
A6: Windows | B6: =Refurbishment!H28+Refurbishment!H39+Refurbishment!H52+Refurbishment!H63+Refurbishment!H74+Refurbishment!H91+Refurbishment!H105+Refurbishment!H117+Refurbishment!H127+Refurbishment!H137+Refurbishment!H147+Refurbishment!H157+Refurbishment!H168+Refurbishment!H178+Refurbishment!H208+Refurbishment!H218+Refurbishment!H228+Refurbishment!H239+Refurbishment!H249+Refurbishment!H259+Refurbishment!H269+Refurbishment!H279+Refurbishment!H289+Refurbishment!H299+Refurbishment!H188+Refurbishment!H198 -> 2800
A7: Kitchen Units & Appliances | B7: =Refurbishment!H67 -> 250
A8: Bathroom and shower suites | B8: =SUM(Refurbishment!H182+Refurbishment!H202+Refurbishment!H232+Refurbishment!H192+Refurbishment!H222+Refurbishment!H273) -> 0
A9: Internal Repairs (Including Additional Section) | B9: =SUM(Refurbishment!H29:H34)+SUM(Refurbishment!H40:H47)+SUM(Refurbishment!H53:H58)+SUM(Refurbishment!H64:H66)+SUM(Refurbishment!H68:H69)+SUM(Refurbishment!H75:H86)+SUM(Refurbishment!H92:H100)+SUM(Refurbishment!H106:H112)+SUM(Refurbishment!H118:H122)+SUM(Refurbishment!H128:H132)+SUM(Refurbishment!H138:H142)+SUM(Refurbishment!H148:H152)+SUM(Refurbishment!H158:H162)+SUM(Refurbishment!H169:H173)+SUM(Refurbishment!H179:H181)+SUM(Refurbishment!H209:H213)+SUM(Refurbishment!H219:H221)+SUM(Refurbishment!H229:H231)+SUM(Refurbishment!H233:H234)+SUM(Refurbishment!H240:H244)+SUM(Refurbishment!H250:H254)+SUM(Refurbishment!H260:H264)+SUM(Refurbishment!H270:H272)+SUM(Refurbishment!H280:H284)+SUM(Refurbishment!H290:H294)+SUM(Refurbishment!H300:H304)+SUM(Refurbishment!H183)+SUM(Refurbishment!H189:H191)+SUM(Refurbishment!H199:H201)+SUM(Refurbishment!H203+Refurbishment!H193)+Refurbishment!J323+Refurbishment!H223+Refurbishment!H274 -> 10285
A10: External Repairs | B10: =SUM(Refurbishment!H325:H341)+SUM(Refurbishment!H348:H352) -> 42477
A11: Roof Repairs | B11: =Refurbishment!J347 -> 13470
A12: Asbestos abatement | B12: =SUM(Compliance!D81:D84) -> 300
A13: Repairs to services and systems (i.e. partial re-wire) | B13: =Compliance!D102-Compliance!D81-Compliance!D82-Compliance!D83-Compliance!D84-B15-B14 -> 2550
A14: New private drainage systems (i.e. new packaged treatment plants, septic tanks and soakaways) | B14: =SUMIF(Compliance!E64:E70,"Capital",Compliance!D64:D70) -> 0
A15: New mechanical and electrical assets (i.e. boilers, central heating systems, full re-wire etc) | B15: =SUMIF(Compliance!E17:E40,"Capital",Compliance!D17:D40)+SUMIF(Compliance!E46:E57,"Capital",Compliance!D46:D57) -> 0
A16: Total | B16: =SUM(B4:B15) -> 73732
A18: Capital | B18: Revenue
A19: =SUMIF(Refurbishment!I24:I162,"Capital",Refurbishment!H24:H162)+SUMIF(Refurbishment!I164:I304,"Capital",Refurbishment!H164:H304)+SUMIF(Refurbishment!I310:I323,"Capital",Refurbishment!H310:H323)+SUMIF(Refurbishment!I325:I352,"Capital",Refurbishment!H325:H352)+SUMIF(Compliance!E17:E40,"Capital",Compliance!D17:D40)+SUMIF(Compliance!E46:E57,"Capital",Compliance!D46:D57)+SUMIF(Compliance!E75:E92,"Capital",Compliance!D75:D92)+SUMIF(Compliance!E64:E70,"Capital",Compliance!D64:D70) -> 0 | B19: =SUMIF(Refurbishment!I24:I162,"Revenue",Refurbishment!H24:H162)+SUMIF(Refurbishment!I164:I304,"Revenue",Refurbishment!H164:H304)+SUMIF(Refurbishment!I310:I323,"Revenue",Refurbishment!H310:H323)+SUMIF(Refurbishment!I325:I352,"Revenue",Refurbishment!H325:H352)+SUMIF(Compliance!E17:E40,"Revenue",Compliance!D17:D40)+SUMIF(Compliance!E46:E57,"Revenue",Compliance!D46:D57)+SUMIF(Compliance!E75:E92,"Revenue",Compliance!D75:D92)+SUMIF(Compliance!E64:E70,"Revenue",Compliance!D64:D70) -> 73732
A20: Capital expenditure shall include the full replacement or new installation of a fixed asset which shall either lengthen the life of the property, increase the usefulness or increase the value. | B20: Revenue expenditure shall include the repair, maintenance and general upkeep of the property including fixed installations, services and the fabric of the building.
A22: Total Compliance Service Costs | B22: =Compliance!D13 -> 4140
A23: Total Compliance | B23: =Compliance!D102 -> 2850
A24: Total Internal Works | B24: =Refurbishment!H305 -> 14935
A25: Total External Works | B25: =Refurbishment!H353 -> 55947
A26: Sub Total | B26: =SUM(B23:B25) -> 73732
A27: Total Contingency (10% of works) | B27: =SUM(B23:B25)*10% -> 7373.2
A28: Sub Total | B28: =B26+B27 -> 81105.2
A29: VAT | B29: =B28*20% -> 16221.04
A31: Project Total Cost | B31: =B28 -> 81105.2
A32: Project Total Cost (inc VAT) | B32: =B28+B29 -> 97326.24
A34: LEAD IN TIME (weeks) | B34: =Refurbishment!C356 -> 0
A35: DURATION OF WORKS (weeks) | B35: =Refurbishment!F356 -> 0

Sheet Sheet1
E1: Revenue expenditure shall include the repair, maintenance and general upkeep of the property including fixed installations, services and the fabric of the building. | F1: COST | G1: Capital expenditure shall include the full replacement or new installation of a fixed asset which shall either lengthen the life of the property, increase the usefulness or increase the value. | H1: COST
B2: Compliance
B3: Capital | E3: · Decoration | G3: · New mechanical and electrical assets (i.e. boilers, central heating systems, full re-wire etc) | H3: As per compliance if non repair
B4: Revenue | E4: · Floor coverings | G4: · New kitchens
E5: · Asbestos abatement | G5: · New bathroom and shower suites
E6: · Damp remediation | G6: · Full re-roof | H6: As per spec
E7: · Internal Repairs | G7: · New private drainage systems (i.e. new packaged treatment plants, septic tanks and soakaways) | H7: As per spec
E8: · Repairs to services and systems (i.e. partial re-wire) | G8: · New windows
E9: · External Repairs | G9: · Additional | H9: 0
E10: · Roof repairs | G10: · Additional | H10: 0
E11: · Additional (non-repair) | H11: 0
E12: Total | G12: Total | H12: 0
E14: Total Compliance Service Costs
E15: Total Compliance
E16: Total General Items
E17: Total Internal Works
E18: Total External Works
E19: Sub Total
E20: Total Contingency (10% of works)
E21: Sub Total
E22: VAT
E25: Project Total Cost
E28: Project Total Cost (inc VAT)
